I'm sorry, but an uncaught exception occurred.

While running game code:
  File "game/script/story/prologue 1.0.rpy", line 6, in script
    e "How is it now?"
Exception: Sayer 'e' is not defined.

-- Full Traceback ------------------------------------------------------------

Full traceback:
  File "game/script/story/prologue 1.0.rpy", line 6, in script
    e "How is it now?"
  File "C:\Users\danie\Documents\Renpy\renpy\ast.py", line 593, in execute
    who = eval_who(self.who, self.who_fast)
  File "C:\Users\danie\Documents\Renpy\renpy\ast.py", line 509, in eval_who
    raise Exception("Sayer '%s' is not defined." % who.encode("utf-8"))
Exception: Sayer 'e' is not defined.

Windows-8-6.2.9200
Ren'Py 6.99.12.4.2187
AMBASSADOR 1.0
